Workbook

Sheet Consolidated_data
A1: ID | B1: Year_Birth | C1: Education | D1: Marital_Status | E1: Income | F1: =if(ISBLANK(E:E),MEDIAN(E:E), E:E) -> Income | G1: Kidhome | H1: Teenhome | I1: Dt_Customer | J1: AMntWines | K1: AmntFruits | L1: AMntMeatProducts | M1: AMntFishProducts | N1: AMntSweetProducts | O1: AMntGoldProds | P1: NumDealsPurchases | Q1: NumWebPurchases | R1: NumCatalogPurchases | S1: NumStorePurchases | T1: NumWebVisitsMonth | U1: Recency | V1: AcceptedCmp3 | W1: AcceptedCmp4 | X1: AcceptedCmp5 | Y1: AcceptedCmp1 | Z1: AcceptedCmp2 | AA1: Complain | AB1: Response | AC1: Age | AD1: Tenure | AE1: Total Spent | AF1: Total_Camp_Responded | AG1: Household Type | AH1: Income band | AI1: Response_Yes/ No | AJ1: Acceptance Cam | AK1: Income_Band_Score | AL1: Normalize_Soend | AM1: Recency | AN1: Num_Web_Purchase | AO1: Cat_Purcahse_Num | AP1: Total_Camp_Num | AQ1: Income_Band_Num | AR1: Response_Score | AS1: Rank | AT1: Renewal_Bucket | AU1: Renewal_Bucket_2
A2: 5524 | B2: 1960 | C2: Graduation | D2: Single | E2: 58138 | F2: =if(ISBLANK(E:E),MEDIAN(E:E), E:E) -> 58138 | G2: 0 | H2: 0 | I2: 2012-09-04 | J2: {=INDEX('Purchase Behaviour'!B:B,MATCH(A2,'Purchase Behaviour'!A:A, 0))} -> 210.0618 | K2: {=INDEX('Purchase Behaviour'!C:C, MATCH($A2,'Purchase Behaviour'!$A:$A, 0))} -> 64.762007 | L2: {=INDEX('Purchase Behaviour'!D:D, MATCH($A2,'Purchase Behaviour'!$A:$A, 0))} -> 318.26953 | M2: {=INDEX('Purchase Behaviour'!E:E, MATCH($A2,'Purchase Behaviour'!$A:$A, 0))} -> 297.70978 | N2: {=INDEX('Purchase Behaviour'!F:F, MATCH($A2,'Purchase Behaviour'!$A:$A, 0))} -> 239.67682 | O2: {=INDEX('Purchase Behaviour'!G:G, MATCH($A2,'Purchase Behaviour'!$A:$A, 0))} -> 207.75903 | P2: {=INDEX('Purchase Behaviour'!H:H, MATCH($A2,'Purchase Behaviour'!$A:$A, 0))} -> 3 | Q2: {=INDEX('Purchase Behaviour'!I:I, MATCH($A2,'Purchase Behaviour'!$A:$A, 0))} -> 8 | R2: {=INDEX('Purchase Behaviour'!J:J, MATCH($A2,'Purchase Behaviour'!$A:$A, 0))} -> 10 | S2: {=INDEX('Purchase Behaviour'!K:K, MATCH($A2,'Purchase Behaviour'!$A:$A, 0))} -> 4 | T2: {=INDEX('Purchase Behaviour'!L:L, MATCH($A2,'Purchase Behaviour'!$A:$A, 0))} -> 7 | U2: {=INDEX('Purchase Behaviour'!M:M, MATCH($A2,'Purchase Behaviour'!$A:$A, 0))} -> 58 | V2: {=INDEX('Campaign Performance'!B:B, MATCH($A2,'Campaign Performance'!$A:$A, 0))} -> 0 | W2: {=INDEX('Campaign Performance'!C:C, MATCH($A2,'Campaign Performance'!$A:$A, 0))} -> 0 | X2: {=INDEX('Campaign Performance'!D:D, MATCH($A2,'Campaign Performance'!$A:$A, 0))} -> 0 | Y2: {=INDEX('Campaign Performance'!E:E, MATCH($A2,'Campaign Performance'!$A:$A, 0))} -> 0 | Z2: {=INDEX('Campaign Performance'!F:F, MATCH($A2,'Campaign Performance'!$A:$A, 0))} -> 0 | AA2: {=INDEX('Campaign Performance'!G:G, MATCH($A2,'Campaign Performance'!$A:$A, 0))} -> 0 | AB2: {=INDEX('Campaign Performance'!H:H, MATCH($A2,'Campaign Performance'!$A:$A, 0))} -> 1 | AC2: =YEAR(TODAY()) - B2 -> 65 | AD2: =DATEDIF(I2,today(),"Y") -> 13 | AE2: =sum(J2:O2) -> 1338.239 | AF2: =sum(V2:Z2) -> 0 | AG2: =if(G2+H2 =0,"No kids",if(G2+H2 = 1,"Small family","Large family")) -> No kids | AH2: =if(E2< 30000, "Low income", if(E2 < 50000, "Mid-income", "High income")) -> High income | AI2: =if(AB2 = 1, "Yes" , "No") -> Yes | AJ2: =if(AF2 = 0, "No Acceptance", if(AF2 = 1, "Low Acceptance", if(AF2 = 2,"Mid Acceptance","High Acceptance"))) -> No Acceptance | AK2: =IF(AH2 = "Low income", 1, if(AH2="Mid income", 2, 3)) -> 3 | AL2: =(AE2-min(AE:AE)) / (MAX(AE:AE)-min(AE:AE)) -> 0.067825675 | AM2: =(max(U:U) -U2)/max(U:U) -> 0.41414141 | AN2: =(Q2-min(Q:Q)) / (max(Q:Q)-min(Q:Q)) -> 0.2962963 | AO2: =(R2-min(R:R))/(max(R:R)-min(R:R)) -> 0.35714286 | AP2: =(AF2-min(AF:AF))/max(AF:AF)-min(AF:AF) -> 0 | AQ2: =(AK2-min(AK:AK))/(max(AK:AK)-min(AK:AK)) -> 1 | AR2: =0.3*AM2+0.25*AL2+0.15*AN2+0.1*AO2+0.1*AQ2+0.1*AP2 -> 0.32135757 | AS2: =RANK(AR2,AR:AR,FALSE) -> 774 | AT2: =(max(AS:AS)-AS2)/(max(AS:AS)-min(AS:AS)) -> 0.65475659 | AU2: =if(AT2<0.5,"Low", if(and(AT2>=0.5,AT2<0.74),"Mid","High")) -> Mid
A3: 2174 | B3: 1960 | C3: Graduation | D3: Single | E3: 46344 | F3: =if(ISBLANK(E:E),MEDIAN(E:E), E:E) -> 46344 | G3: 0 | H3: 1 | I3: 2014-03-08 | J3: {=INDEX('Purchase Behaviour'!B:B,MATCH(A3,'Purchase Behaviour'!A:A, 0))} -> 244.03731 | K3: {=INDEX('Purchase Behaviour'!C:C, MATCH($A3,'Purchase Behaviour'!$A:$A, 0))} -> 149.98172 | L3: {=INDEX('Purchase Behaviour'!D:D, MATCH($A3,'Purchase Behaviour'!$A:$A, 0))} -> 145.15352 | M3: {=INDEX('Purchase Behaviour'!E:E, MATCH($A3,'Purchase Behaviour'!$A:$A, 0))} -> 136.42857 | N3: {=INDEX('Purchase Behaviour'!F:F, MATCH($A3,'Purchase Behaviour'!$A:$A, 0))} -> 207.28853 | O3: {=INDEX('Purchase Behaviour'!G:G, MATCH($A3,'Purchase Behaviour'!$A:$A, 0))} -> 180.43213 | P3: {=INDEX('Purchase Behaviour'!H:H, MATCH($A3,'Purchase Behaviour'!$A:$A, 0))} -> 2 | Q3: {=INDEX('Purchase Behaviour'!I:I, MATCH($A3,'Purchase Behaviour'!$A:$A, 0))} -> 1 | R3: {=INDEX('Purchase Behaviour'!J:J, MATCH($A3,'Purchase Behaviour'!$A:$A, 0))} -> 1 | S3: {=INDEX('Purchase Behaviour'!K:K, MATCH($A3,'Purchase Behaviour'!$A:$A, 0))} -> 2 | T3: {=INDEX('Purchase Behaviour'!L:L, MATCH($A3,'Purchase Behaviour'!$A:$A, 0))} -> 5 | U3: {=INDEX('Purchase Behaviour'!M:M, MATCH($A3,'Purchase Behaviour'!$A:$A, 0))} -> 38 | V3: {=INDEX('Campaign Performance'!B:B, MATCH(A3,'Campaign Performance'!A:A, 0))} -> 0 | W3: {=INDEX('Campaign Performance'!C:C, MATCH($A3,'Campaign Performance'!$A:$A, 0))} -> 0 | X3: {=INDEX('Campaign Performance'!D:D, MATCH($A3,'Campaign Performance'!$A:$A, 0))} -> 0 | Y3: {=INDEX('Campaign Performance'!E:E, MATCH($A3,'Campaign Performance'!$A:$A, 0))} -> 0 | Z3: {=INDEX('Campaign Performance'!F:F, MATCH($A3,'Campaign Performance'!$A:$A, 0))} -> 0 | AA3: {=INDEX('Campaign Performance'!G:G, MATCH($A3,'Campaign Performance'!$A:$A, 0))} -> 0 | AB3: {=INDEX('Campaign Performance'!H:H, MATCH($A3,'Campaign Performance'!$A:$A, 0))} -> 0 | AC3: =YEAR(TODAY()) - B3 -> 65 | AD3: =DATEDIF(I3,today(),"Y") -> 11 | AE3: =sum(J3:O3) -> 1063.3218 | AF3: =sum(V3:Z3) -> 0 | AG3: =if(G3+H3 =0,"No kids",if(G3+H3 = 1,"Small family","Large family")) -> Small family | AH3: =if(E3< 30000, "Low income", if(E3 < 50000, "Mid income", "High income")) -> Mid income | AI3: =if(AB3 = 1, "Yes" , "No") -> No | AJ3: =if(AF3 = 0, "No Acceptance", if(AF3 = 1, "Low Acceptance", if(AF3 = 2,"Mid Acceptance","High Acceptance"))) -> No Acceptance | AK3: =IF(AH3 = "Low income", 1, if(AH3="Mid income", 2, 3)) -> 2 | AL3: =(AE3-min(AE:AE)) / (MAX(AE:AE)-min(AE:AE)) -> 0.053892107 | AM3: =(max(U:U) -U3)/max(U:U) -> 0.61616162 | AN3: =(Q3-min(Q:Q)) / (max(Q:Q)-min(Q:Q)) -> 0.037037037 | AO3: =(R3-min(R:R))/(max(R:R)-min(R:R)) -> 0.035714286 | AP3: =(AF3-min(AF:AF))/max(AF:AF)-min(AF:AF) -> 0 | AQ3: =(AK3-min(AK:AK))/(max(AK:AK)-min(AK:AK)) -> 0.5 | AR3: =0.3*AM3+0.25*AL3+0.15*AN3+0.1*AO3+0.1*AQ3+0.1*AP3 -> 0.2574485 | AS3: =RANK(AR3,AR:AR,FALSE) -> 1269 | AT3: =(max(AS:AS)-AS3)/(max(AS:AS)-min(AS:AS)) -> 0.43367575 | AU3: =if(AT3<0.5,"Low", if(and(AT3>=0.5,AT3<0.74),"Mid","High")) -> Low
A4: 4141 | B4: 1965 | C4: Graduation | D4: Together | E4: 71613 | F4: =if(ISBLANK(E:E),MEDIAN(E:E), E:E) -> 71613 | G4: 0 | H4: 0 | I4: 2013-08-21 | J4: {=INDEX('Purchase Behaviour'!B:B,MATCH(A4,'Purchase Behaviour'!A:A, 0))} -> 300.53131 | K4: {=INDEX('Purchase Behaviour'!C:C, MATCH($A4,'Purchase Behaviour'!$A:$A, 0))} -> 399.88157 | L4: {=INDEX('Purchase Behaviour'!D:D, MATCH($A4,'Purchase Behaviour'!$A:$A, 0))} -> 448.29181 | M4: {=INDEX('Purchase Behaviour'!E:E, MATCH($A4,'Purchase Behaviour'!$A:$A, 0))} -> 501.71276 | N4: {=INDEX('Purchase Behaviour'!F:F, MATCH($A4,'Purchase Behaviour'!$A:$A, 0))} -> 349.25813 | O4: {=INDEX('Purchase Behaviour'!G:G, MATCH($A4,'Purchase Behaviour'!$A:$A, 0))} -> 380.77796 | P4: {=INDEX('Purchase Behaviour'!H:H, MATCH($A4,'Purchase Behaviour'!$A:$A, 0))} -> 1 | Q4: {=INDEX('Purchase Behaviour'!I:I, MATCH($A4,'Purchase Behaviour'!$A:$A, 0))} -> 8 | R4: {=INDEX('Purchase Behaviour'!J:J, MATCH($A4,'Purchase Behaviour'!$A:$A, 0))} -> 2 | S4: {=INDEX('Purchase Behaviour'!K:K, MATCH($A4,'Purchase Behaviour'!$A:$A, 0))} -> 10 | T4: {=INDEX('Purchase Behaviour'!L:L, MATCH($A4,'Purchase Behaviour'!$A:$A, 0))} -> 4 | U4: {=INDEX('Purchase Behaviour'!M:M, MATCH($A4,'Purchase Behaviour'!$A:$A, 0))} -> 26 | V4: {=INDEX('Campaign Performance'!B:B, MATCH(A4,'Campaign Performance'!A:A, 0))} -> 0 | W4: {=INDEX('Campaign Performance'!C:C, MATCH($A4,'Campaign Performance'!$A:$A, 0))} -> 0 | X4: {=INDEX('Campaign Performance'!D:D, MATCH($A4,'Campaign Performance'!$A:$A, 0))} -> 0 | Y4: {=INDEX('Campaign Performance'!E:E, MATCH($A4,'Campaign Performance'!$A:$A, 0))} -> 0 | Z4: {=INDEX('Campaign Performance'!F:F, MATCH($A4,'Campaign Performance'!$A:$A, 0))} -> 0 | AA4: {=INDEX('Campaign Performance'!G:G, MATCH($A4,'Campaign Performance'!$A:$A, 0))} -> 0 | AB4: {=INDEX('Campaign Performance'!H:H, MATCH($A4,'Campaign Performance'!$A:$A, 0))} -> 0 | AC4: =YEAR(TODAY()) - B4 -> 60 | AD4: =DATEDIF(I4,today(),"Y") -> 12 | AE4: =sum(J4:O4) -> 2380.4535 | AF4: =sum(V4:Z4) -> 0 | AG4: =if(G4+H4 =0,"No kids",if(G4+H4 = 1,"Small family","Large family")) -> No kids | AH4: =if(E4< 30000, "Low income", if(E4 < 50000, "Mid income", "High income")) -> High income | AI4: =if(AB4 = 1, "Yes" , "No") -> No | AJ4: =if(AF4 = 0, "No Acceptance", if(AF4 = 1, "Low Acceptance", if(AF4 = 2,"Mid Acceptance","High Acceptance"))) -> No Acceptance | AK4: =IF(AH4 = "Low income", 1, if(AH4="Mid income", 2, 3)) -> 3 | AL4: =(AE4-min(AE:AE)) / (MAX(AE:AE)-min(AE:AE)) -> 0.12064801 | AM4: =(max(U:U) -U4)/max(U:U) -> 0.73737374 | AN4: =(Q4-min(Q:Q)) / (max(Q:Q)-min(Q:Q)) -> 0.2962963 | AO4: =(R4-min(R:R))/(max(R:R)-min(R:R)) -> 0.071428571 | AP4: =(AF4-min(AF:AF))/max(AF:AF)-min(AF:AF) -> 0 | AQ4: =(AK4-min(AK:AK))/(max(AK:AK)-min(AK:AK)) -> 1 | AR4: =0.3*AM4+0.25*AL4+0.15*AN4+0.1*AO4+0.1*AQ4+0.1*AP4 -> 0.40296143 | AS4: =RANK(AR4,AR:AR,FALSE) -> 321 | AT4: =(max(AS:AS)-AS4)/(max(AS:AS)-min(AS:AS)) -> 0.85707905 | AU4: =if(AT4<0.5,"Low", if(and(AT4>=0.5,AT4<0.74),"Mid","High")) -> High
A5: 6182 | B5: 1984 | C5: Graduation | D5: Together | E5: 26646 | F5: =if(ISBLANK(E:E),MEDIAN(E:E), E:E) -> 26646 | G5: 0 | H5: 0 | I5: 2014-02-10 | J5: {=INDEX('Purchase Behaviour'!B:B,MATCH(A5,'Purchase Behaviour'!A:A, 0))} -> 135.20443 | K5: {=INDEX('Purchase Behaviour'!C:C, MATCH(A5,'Purchase Behaviour'!A:A, 0))} -> 59.193005 | L5: {=INDEX('Purchase Behaviour'!D:D, MATCH($A5,'Purchase Behaviour'!$A:$A, 0))} -> 112.41595 | M5: {=INDEX('Purchase Behaviour'!E:E, MATCH($A5,'Purchase Behaviour'!$A:$A, 0))} -> 112.60358 | N5: {=INDEX('Purchase Behaviour'!F:F, MATCH($A5,'Purchase Behaviour'!$A:$A, 0))} -> 106.65844 | O5: {=INDEX('Purchase Behaviour'!G:G, MATCH($A5,'Purchase Behaviour'!$A:$A, 0))} -> 125.82921 | P5: {=INDEX('Purchase Behaviour'!H:H, MATCH($A5,'Purchase Behaviour'!$A:$A, 0))} -> 2 | Q5: {=INDEX('Purchase Behaviour'!I:I, MATCH($A5,'Purchase Behaviour'!$A:$A, 0))} -> 2 | R5: {=INDEX('Purchase Behaviour'!J:J, MATCH($A5,'Purchase Behaviour'!$A:$A, 0))} -> 0 | S5: {=INDEX('Purchase Behaviour'!K:K, MATCH($A5,'Purchase Behaviour'!$A:$A, 0))} -> 4 | T5: {=INDEX('Purchase Behaviour'!L:L, MATCH($A5,'Purchase Behaviour'!$A:$A, 0))} -> 6 | U5: {=INDEX('Purchase Behaviour'!M:M, MATCH($A5,'Purchase Behaviour'!$A:$A, 0))} -> 26 | V5: {=INDEX('Campaign Performance'!B:B, MATCH(A5,'Campaign Performance'!A:A, 0))} -> 0 | W5: {=INDEX('Campaign Performance'!C:C, MATCH($A5,'Campaign Performance'!$A:$A, 0))} -> 0 | X5: {=INDEX('Campaign Performance'!D:D, MATCH($A5,'Campaign Performance'!$A:$A, 0))} -> 0 | Y5: {=INDEX('Campaign Performance'!E:E, MATCH($A5,'Campaign Performance'!$A:$A, 0))} -> 0 | Z5: {=INDEX('Campaign Performance'!F:F, MATCH($A5,'Campaign Performance'!$A:$A, 0))} -> 0 | AA5: {=INDEX('Campaign Performance'!G:G, MATCH($A5,'Campaign Performance'!$A:$A, 0))} -> 0 | AB5: {=INDEX('Campaign Performance'!H:H, MATCH($A5,'Campaign Performance'!$A:$A, 0))} -> 0 | AC5: =YEAR(TODAY()) - B5 -> 41 | AD5: =DATEDIF(I5,today(),"Y") -> 11 | AE5: =sum(J5:O5) -> 651.90462 | AF5: =sum(V5:Z5) -> 0 | AG5: =if(G5+H5 =0,"No kids",if(G5+H5 = 1,"Small family","Large family")) -> No kids | AH5: =if(E5< 30000, "Low income", if(E5 < 50000, "Mid income", "High income")) -> Low income | AI5: =if(AB5 = 1, "Yes" , "No") -> No | AJ5: =if(AF5 = 0, "No Acceptance", if(AF5 = 1, "Low Acceptance", if(AF5 = 2,"Mid Acceptance","High Acceptance"))) -> No Acceptance | AK5: =IF(AH5 = "Low income", 1, if(AH5="Mid income", 2, 3)) -> 1 | AL5: =(AE5-min(AE:AE)) / (MAX(AE:AE)-min(AE:AE)) -> 0.03304034 | AM5: =(max(U:U) -U5)/max(U:U) -> 0.73737374 | AN5: =(Q5-min(Q:Q)) / (max(Q:Q)-min(Q:Q)) -> 0.074074074 | AO5: =(R5-min(R:R))/(max(R:R)-min(R:R)) -> 0 | AP5: =(AF5-min(AF:AF))/max(AF:AF)-min(AF:AF) -> 0 | AQ5: =(AK5-min(AK:AK))/(max(AK:AK)-min(AK:AK)) -> 0 | AR5: =0.3*AM5+0.25*AL5+0.15*AN5+0.1*AO5+0.1*AQ5+0.1*AP5 -> 0.24058332 | AS5: =RANK(AR5,AR:AR,FALSE) -> 1384 | AT5: =(max(AS:AS)-AS5)/(max(AS:AS)-min(AS:AS)) -> 0.38231353 | AU5: =if(AT5<0.5,"Low", if(and(AT5>=0.5,AT5<0.74),"Mid","High")) -> Low
A6: 5324 | B6: 1981 | C6: PhD | D6: Married | E6: 58293 | F6: =if(ISBLANK(E:E),MEDIAN(E:E), E:E) -> 58293 | G6: 0 | H6: 1 | I6: 2014-01-19 | J6: {=INDEX('Purchase Behaviour'!B:B,MATCH(A6,'Purchase Behaviour'!A:A, 0))} -> 259.33834 | K6: {=INDEX('Purchase Behaviour'!C:C, MATCH(A6,'Purchase Behaviour'!A:A, 0))} -> 190.89185 | L6: {=INDEX('Purchase Behaviour'!D:D, MATCH($A6,'Purchase Behaviour'!$A:$A, 0))} -> 265.4484 | M6: {=INDEX('Purchase Behaviour'!E:E, MATCH($A6,'Purchase Behaviour'!$A:$A, 0))} -> 221.88874 | N6: {=INDEX('Purchase Behaviour'!F:F, MATCH($A6,'Purchase Behaviour'!$A:$A, 0))} -> 45.142446 | O6: {=INDEX('Purchase Behaviour'!G:G, MATCH($A6,'Purchase Behaviour'!$A:$A, 0))} -> 154.23018 | P6: {=INDEX('Purchase Behaviour'!H:H, MATCH($A6,'Purchase Behaviour'!$A:$A, 0))} -> 5 | Q6: {=INDEX('Purchase Behaviour'!I:I, MATCH($A6,'Purchase Behaviour'!$A:$A, 0))} -> 5 | R6: {=INDEX('Purchase Behaviour'!J:J, MATCH($A6,'Purchase Behaviour'!$A:$A, 0))} -> 3 | S6: {=INDEX('Purchase Behaviour'!K:K, MATCH($A6,'Purchase Behaviour'!$A:$A, 0))} -> 6 | T6: {=INDEX('Purchase Behaviour'!L:L, MATCH($A6,'Purchase Behaviour'!$A:$A, 0))} -> 5 | U6: {=INDEX('Purchase Behaviour'!M:M, MATCH($A6,'Purchase Behaviour'!$A:$A, 0))} -> 94 | V6: {=INDEX('Campaign Performance'!B:B, MATCH(A6,'Campaign Performance'!A:A, 0))} -> 0 | W6: {=INDEX('Campaign Performance'!C:C, MATCH($A6,'Campaign Performance'!$A:$A, 0))} -> 0 | X6: {=INDEX('Campaign Performance'!D:D, MATCH($A6,'Campaign Performance'!$A:$A, 0))} -> 0 | Y6: {=INDEX('Campaign Performance'!E:E, MATCH($A6,'Campaign Performance'!$A:$A, 0))} -> 0 | Z6: {=INDEX('Campaign Performance'!F:F, MATCH($A6,'Campaign Performance'!$A:$A, 0))} -> 0 | AA6: {=INDEX('Campaign Performance'!G:G, MATCH($A6,'Campaign Performance'!$A:$A, 0))} -> 1 | AB6: {=INDEX('Campaign Performance'!H:H, MATCH($A6,'Campaign Performance'!$A:$A, 0))} -> 0 | AC6: =YEAR(TODAY()) - B6 -> 44 | AD6: =DATEDIF(I6,today(),"Y") -> 11 | AE6: =sum(J6:O6) -> 1136.94 | AF6: =sum(V6:Z6) -> 0 | AG6: =if(G6+H6 =0,"No kids",if(G6+H6 = 1,"Small family","Large family")) -> Small family | AH6: =if(E6< 30000, "Low income", if(E6 < 50000, "Mid income", "High income")) -> High income | AI6: =if(AB6 = 1, "Yes" , "No") -> No | AJ6: =if(AF6 = 0, "No Acceptance", if(AF6 = 1, "Low Acceptance", if(AF6 = 2,"Mid Acceptance","High Acceptance"))) -> No Acceptance | AK6: =IF(AH6 = "Low income", 1, if(AH6="Mid income", 2, 3)) -> 3 | AL6: =(AE6-min(AE:AE)) / (MAX(AE:AE)-min(AE:AE)) -> 0.057623281 | AM6: =(max(U:U) -U6)/max(U:U) -> 0.050505051 | AN6: =(Q6-min(Q:Q)) / (max(Q:Q)-min(Q:Q)) -> 0.18518519 | AO6: =(R6-min(R:R))/(max(R:R)-min(R:R)) -> 0.10714286 | AP6: =(AF6-min(AF:AF))/max(AF:AF)-min(AF:AF) -> 0 | AQ6: =(AK6-min(AK:AK))/(max(AK:AK)-min(AK:AK)) -> 1 | AR6: =0.3*AM6+0.25*AL6+0.15*AN6+0.1*AO6+0.1*AQ6+0.1*AP6 -> 0.1680494 | AS6: =RANK(AR6,AR:AR,FALSE) -> 1853 | AT6: =(max(AS:AS)-AS6)/(max(AS:AS)-min(AS:AS)) -> 0.17284502 | AU6: =if(AT6<0.5,"Low", if(and(AT6>=0.5,AT6<0.74),"Mid","High")) -> Low
A7: 7446 | B7: 1967 | C7: Master | D7: Together | E7: 62513 | F7: =if(ISBLANK(E:E),MEDIAN(E:E), E:E) -> 62513 | G7: 0 | H7: 0 | I7: 2013-09-09 | J7: {=INDEX('Purchase Behaviour'!B:B,MATCH(A7,'Purchase Behaviour'!A:A, 0))} -> 307.63176 | K7: {=INDEX('Purchase Behaviour'!C:C, MATCH(A7,'Purchase Behaviour'!A:A, 0))} -> 403.63544 | L7: {=INDEX('Purchase Behaviour'!D:D, MATCH($A7,'Purchase Behaviour'!$A:$A, 0))} -> 66.792211 | M7: {=INDEX('Purchase Behaviour'!E:E, MATCH($A7,'Purchase Behaviour'!$A:$A, 0))} -> 215.80823 | N7: {=INDEX('Purchase Behaviour'!F:F, MATCH($A7,'Purchase Behaviour'!$A:$A, 0))} -> 340.41921 | O7: {=INDEX('Purchase Behaviour'!G:G, MATCH($A7,'Purchase Behaviour'!$A:$A, 0))} -> 383.18074 | P7: {=INDEX('Purchase Behaviour'!H:H, MATCH($A7,'Purchase Behaviour'!$A:$A, 0))} -> 2 | Q7: {=INDEX('Purchase Behaviour'!I:I, MATCH($A7,'Purchase Behaviour'!$A:$A, 0))} -> 6 | R7: {=INDEX('Purchase Behaviour'!J:J, MATCH($A7,'Purchase Behaviour'!$A:$A, 0))} -> 4 | S7: {=INDEX('Purchase Behaviour'!K:K, MATCH($A7,'Purchase Behaviour'!$A:$A, 0))} -> 10 | T7: {=INDEX('Purchase Behaviour'!L:L, MATCH($A7,'Purchase Behaviour'!$A:$A, 0))} -> 6 | U7: {=INDEX('Purchase Behaviour'!M:M, MATCH($A7,'Purchase Behaviour'!$A:$A, 0))} -> 16 | V7: {=INDEX('Campaign Performance'!B:B, MATCH(A7,'Campaign Performance'!A:A, 0))} -> 0 | W7: {=INDEX('Campaign Performance'!C:C, MATCH($A7,'Campaign Performance'!$A:$A, 0))} -> 0 | X7: {=INDEX('Campaign Performance'!D:D, MATCH($A7,'Campaign Performance'!$A:$A, 0))} -> 0 | Y7: {=INDEX('Campaign Performance'!E:E, MATCH($A7,'Campaign Performance'!$A:$A, 0))} -> 0 | Z7: {=INDEX('Campaign Performance'!F:F, MATCH($A7,'Campaign Performance'!$A:$A, 0))} -> 0 | AA7: {=INDEX('Campaign Performance'!G:G, MATCH($A7,'Campaign Performance'!$A:$A, 0))} -> 0 | AB7: {=INDEX('Campaign Performance'!H:H, MATCH($A7,'Campaign Performance'!$A:$A, 0))} -> 0 | AC7: =YEAR(TODAY()) - B7 -> 58 | AD7: =DATEDIF(I7,today(),"Y") -> 12 | AE7: =sum(J7:O7) -> 1717.4676 | AF7: =sum(V7:Z7) -> 0 | AG7: =if(G7+H7 =0,"No kids",if(G7+H7 = 1,"Small family","Large family")) -> No kids | AH7: =if(E7< 30000, "Low income", if(E7 < 50000, "Mid income", "High income")) -> High income | AI7: =if(AB7 = 1, "Yes" , "No") -> No | AJ7: =if(AF7 = 0, "No Acceptance", if(AF7 = 1, "Low Acceptance", if(AF7 = 2,"Mid Acceptance","High Acceptance"))) -> No Acceptance | AK7: =IF(AH7 = "Low income", 1, if(AH7="Mid income", 2, 3)) -> 3 | AL7: =(AE7-min(AE:AE)) / (MAX(AE:AE)-min(AE:AE)) -> 0.087046037 | AM7: =(max(U:U) -U7)/max(U:U) -> 0.83838384 | AN7: =(Q7-min(Q:Q)) / (max(Q:Q)-min(Q:Q)) -> 0.22222222 | AO7: =(R7-min(R:R))/(max(R:R)-min(R:R)) -> 0.14285714 | AP7: =(AF7-min(AF:AF))/max(AF:AF)-min(AF:AF) -> 0 | AQ7: =(AK7-min(AK:AK))/(max(AK:AK)-min(AK:AK)) -> 1 | AR7: =0.3*AM7+0.25*AL7+0.15*AN7+0.1*AO7+0.1*AQ7+0.1*AP7 -> 0.42089571 | AS7: =RANK(AR7,AR:AR,FALSE) -> 258 | AT7: =(max(AS:AS)-AS7)/(max(AS:AS)-min(AS:AS)) -> 0.88521661 | AU7: =if(AT7<0.5,"Low", if(and(AT7>=0.5,AT7<0.74),"Mid","High")) -> High
A8: 965 | B8: 1971 | C8: Graduation | D8: Divorced | E8: 55635 | F8: =if(ISBLANK(E:E),MEDIAN(E:E), E:E) -> 55635 | G8: 0 | H8: 0 | I8: 2012-11-13 | J8: {=INDEX('Purchase Behaviour'!B:B,MATCH(A8,'Purchase Behaviour'!A:A, 0))} -> 230.42185 | K8: {=INDEX('Purchase Behaviour'!C:C, MATCH(A8,'Purchase Behaviour'!A:A, 0))} -> 208.04582 | L8: {=INDEX('Purchase Behaviour'!D:D, MATCH($A8,'Purchase Behaviour'!$A:$A, 0))} -> 370.11399 | M8: {=INDEX('Purchase Behaviour'!E:E, MATCH($A8,'Purchase Behaviour'!$A:$A, 0))} -> 334.02713 | N8: {=INDEX('Purchase Behaviour'!F:F, MATCH($A8,'Purchase Behaviour'!$A:$A, 0))} -> 339.35352 | O8: {=INDEX('Purchase Behaviour'!G:G, MATCH($A8,'Purchase Behaviour'!$A:$A, 0))} -> 226.33709 | P8: {=INDEX('Purchase Behaviour'!H:H, MATCH($A8,'Purchase Behaviour'!$A:$A, 0))} -> 4 | Q8: {=INDEX('Purchase Behaviour'!I:I, MATCH($A8,'Purchase Behaviour'!$A:$A, 0))} -> 7 | R8: {=INDEX('Purchase Behaviour'!J:J, MATCH($A8,'Purchase Behaviour'!$A:$A, 0))} -> 3 | S8: {=INDEX('Purchase Behaviour'!K:K, MATCH($A8,'Purchase Behaviour'!$A:$A, 0))} -> 7 | T8: {=INDEX('Purchase Behaviour'!L:L, MATCH($A8,'Purchase Behaviour'!$A:$A, 0))} -> 6 | U8: {=INDEX('Purchase Behaviour'!M:M, MATCH($A8,'Purchase Behaviour'!$A:$A, 0))} -> 34 | V8: {=INDEX('Campaign Performance'!B:B, MATCH(A8,'Campaign Performance'!A:A, 0))} -> 0 | W8: {=INDEX('Campaign Performance'!C:C, MATCH($A8,'Campaign Performance'!$A:$A, 0))} -> 0 | X8: {=INDEX('Campaign Performance'!D:D, MATCH($A8,'Campaign Performance'!$A:$A, 0))} -> 0 | Y8: {=INDEX('Campaign Performance'!E:E, MATCH($A8,'Campaign Performance'!$A:$A, 0))} -> 0 | Z8: {=INDEX('Campaign Performance'!F:F, MATCH($A8,'Campaign Performance'!$A:$A, 0))} -> 0 | AA8: {=INDEX('Campaign Performance'!G:G, MATCH($A8,'Campaign Performance'!$A:$A, 0))} -> 0 | AB8: {=INDEX('Campaign Performance'!H:H, MATCH($A8,'Campaign Performance'!$A:$A, 0))} -> 0 | AC8: =YEAR(TODAY()) - B8 -> 54 | AD8: =DATEDIF(I8,today(),"Y") -> 13 | AE8: =sum(J8:O8) -> 1708.2994 | AF8: =sum(V8:Z8) -> 0 | AG8: =if(G8+H8 =0,"No kids",if(G8+H8 = 1,"Small family","Large family")) -> No kids | AH8: =if(E8< 30000, "Low income", if(E8 < 50000, "Mid income", "High income")) -> High income | AI8: =if(AB8 = 1, "Yes" , "No") -> No | AJ8: =if(AF8 = 0, "No Acceptance", if(AF8 = 1, "Low Acceptance", if(AF8 = 2,"Mid Acceptance","High Acceptance"))) -> No Acceptance | AK8: =IF(AH8 = "Low income", 1, if(AH8="Mid income", 2, 3)) -> 3 | AL8: =(AE8-min(AE:AE)) / (MAX(AE:AE)-min(AE:AE)) -> 0.086581368 | AM8: =(max(U:U) -U8)/max(U:U) -> 0.65656566 | AN8: =(Q8-min(Q:Q)) / (max(Q:Q)-min(Q:Q)) -> 0.25925926 | AO8: =(R8-min(R:R))/(max(R:R)-min(R:R)) -> 0.10714286 | AP8: =(AF8-min(AF:AF))/max(AF:AF)-min(AF:AF) -> 0 | AQ8: =(AK8-min(AK:AK))/(max(AK:AK)-min(AK:AK)) -> 1 | AR8: =0.3*AM8+0.25*AL8+0.15*AN8+0.1*AO8+0.1*AQ8+0.1*AP8 -> 0.36821821 | AS8: =RANK(AR8,AR:AR,FALSE) -> 483 | AT8: =(max(AS:AS)-AS8)/(max(AS:AS)-min(AS:AS)) -> 0.78472532 | AU8: =if(AT8<0.5,"Low", if(and(AT8>=0.5,AT8<0.74),"Mid","High")) -> High
A9: 6177 | B9: 1985 | C9: PhD | D9: Married | E9: 33454 | F9: =if(ISBLANK(E:E),MEDIAN(E:E), E:E) -> 33454 | G9: 1 | H9: 0 | I9: 2013-05-08 | J9: {=INDEX('Purchase Behaviour'!B:B,MATCH(A9,'Purchase Behaviour'!A:A, 0))} -> 217.12342 | K9: {=INDEX('Purchase Behaviour'!C:C, MATCH(A9,'Purchase Behaviour'!A:A, 0))} -> 60.440953 | L9: {=INDEX('Purchase Behaviour'!D:D, MATCH($A9,'Purchase Behaviour'!$A:$A, 0))} -> 218.02168 | M9: {=INDEX('Purchase Behaviour'!E:E, MATCH($A9,'Purchase Behaviour'!$A:$A, 0))} -> 156.66735 | N9: {=INDEX('Purchase Behaviour'!F:F, MATCH($A9,'Purchase Behaviour'!$A:$A, 0))} -> 166.67995 | O9: {=INDEX('Purchase Behaviour'!G:G, MATCH($A9,'Purchase Behaviour'!$A:$A, 0))} -> 111.65566 | P9: {=INDEX('Purchase Behaviour'!H:H, MATCH($A9,'Purchase Behaviour'!$A:$A, 0))} -> 2 | Q9: {=INDEX('Purchase Behaviour'!I:I, MATCH($A9,'Purchase Behaviour'!$A:$A, 0))} -> 4 | R9: {=INDEX('Purchase Behaviour'!J:J, MATCH($A9,'Purchase Behaviour'!$A:$A, 0))} -> 0 | S9: {=INDEX('Purchase Behaviour'!K:K, MATCH($A9,'Purchase Behaviour'!$A:$A, 0))} -> 4 | T9: {=INDEX('Purchase Behaviour'!L:L, MATCH($A9,'Purchase Behaviour'!$A:$A, 0))} -> 8 | U9: {=INDEX('Purchase Behaviour'!M:M, MATCH($A9,'Purchase Behaviour'!$A:$A, 0))} -> 32 | V9: {=INDEX('Campaign Performance'!B:B, MATCH(A9,'Campaign Performance'!A:A, 0))} -> 0 | W9: {=INDEX('Campaign Performance'!C:C, MATCH($A9,'Campaign Performance'!$A:$A, 0))} -> 0 | X9: {=INDEX('Campaign Performance'!D:D, MATCH($A9,'Campaign Performance'!$A:$A, 0))} -> 0 | Y9: {=INDEX('Campaign Performance'!E:E, MATCH($A9,'Campaign Performance'!$A:$A, 0))} -> 0 | Z9: {=INDEX('Campaign Performance'!F:F, MATCH($A9,'Campaign Performance'!$A:$A, 0))} -> 0 | AA9: {=INDEX('Campaign Performance'!G:G, MATCH($A9,'Campaign Performance'!$A:$A, 0))} -> 0 | AB9: {=INDEX('Campaign Performance'!H:H, MATCH($A9,'Campaign Performance'!$A:$A, 0))} -> 0 | AC9: =YEAR(TODAY()) - B9 -> 40 | AD9: =DATEDIF(I9,today(),"Y") -> 12 | AE9: =sum(J9:O9) -> 930.58903 | AF9: =sum(V9:Z9) -> 0 | AG9: =if(G9+H9 =0,"No kids",if(G9+H9 = 1,"Small family","Large family")) -> Small family | AH9: =if(E9< 30000, "Low income", if(E9 < 50000, "Mid income", "High income")) -> Mid income | AI9: =if(AB9 = 1, "Yes" , "No") -> No | AJ9: =if(AF9 = 0, "No Acceptance", if(AF9 = 1, "Low Acceptance", if(AF9 = 2,"Mid Acceptance","High Acceptance"))) -> No Acceptance | AK9: =IF(AH9 = "Low income", 1, if(AH9="Mid income", 2, 3)) -> 2 | AL9: =(AE9-min(AE:AE)) / (MAX(AE:AE)-min(AE:AE)) -> 0.047164842 | AM9: =(max(U:U) -U9)/max(U:U) -> 0.67676768 | AN9: =(Q9-min(Q:Q)) / (max(Q:Q)-min(Q:Q)) -> 0.14814815 | AO9: =(R9-min(R:R))/(max(R:R)-min(R:R)) -> 0 | AP9: =(AF9-min(AF:AF))/max(AF:AF)-min(AF:AF) -> 0 | AQ9: =(AK9-min(AK:AK))/(max(AK:AK)-min(AK:AK)) -> 0.5 | AR9: =0.3*AM9+0.25*AL9+0.15*AN9+0.1*AO9+0.1*AQ9+0.1*AP9 -> 0.28704374 | AS9: =RANK(AR9,AR:AR,FALSE) -> 1059 | AT9: =(max(AS:AS)-AS9)/(max(AS:AS)-min(AS:AS)) -> 0.52746762 | AU9: =if(AT9<0.5,"Low", if(and(AT9>=0.5,AT9<0.74),"Mid","High")) -> Mid
A10: 4855 | B10: 1974 | C10: PhD | D10: Together | E10: 30351 | F10: =if(ISBLANK(E:E),MEDIAN(E:E), E:E) -> 30351 | G10: 0 | H10: 0 | I10: 2013-06-06 | J10: {=INDEX('Purchase Behaviour'!B:B,MATCH(A10,'Purchase Behaviour'!A:A, 0))} -> 60.924715 | K10: {=INDEX('Purchase Behaviour'!C:C, MATCH(A10,'Purchase Behaviour'!A:A, 0))} -> 150.23306 | L10: {=INDEX('Purchase Behaviour'!D:D, MATCH($A10,'Purchase Behaviour'!$A:$A, 0))} -> 170.85263 | M10: {=INDEX('Purchase Behaviour'!E:E, MATCH($A10,'Purchase Behaviour'!$A:$A, 0))} -> 177.88387 | N10: {=INDEX('Purchase Behaviour'!F:F, MATCH($A10,'Purchase Behaviour'!$A:$A, 0))} -> 172.86881 | O10: {=INDEX('Purchase Behaviour'!G:G, MATCH($A10,'Purchase Behaviour'!$A:$A, 0))} -> 162.33727 | P10: {=INDEX('Purchase Behaviour'!H:H, MATCH($A10,'Purchase Behaviour'!$A:$A, 0))} -> 1 | Q10: {=INDEX('Purchase Behaviour'!I:I, MATCH($A10,'Purchase Behaviour'!$A:$A, 0))} -> 3 | R10: {=INDEX('Purchase Behaviour'!J:J, MATCH($A10,'Purchase Behaviour'!$A:$A, 0))} -> 0 | S10: {=INDEX('Purchase Behaviour'!K:K, MATCH($A10,'Purchase Behaviour'!$A:$A, 0))} -> 2 | T10: {=INDEX('Purchase Behaviour'!L:L, MATCH($A10,'Purchase Behaviour'!$A:$A, 0))} -> 9 | U10: {=INDEX('Purchase Behaviour'!M:M, MATCH($A10,'Purchase Behaviour'!$A:$A, 0))} -> 19 | V10: {=INDEX('Campaign Performance'!B:B, MATCH(A10,'Campaign Performance'!A:A, 0))} -> 0 | W10: {=INDEX('Campaign Performance'!C:C, MATCH($A10,'Campaign Performance'!$A:$A, 0))} -> 0 | X10: {=INDEX('Campaign Performance'!D:D, MATCH($A10,'Campaign Performance'!$A:$A, 0))} -> 0 | Y10: {=INDEX('Campaign Performance'!E:E, MATCH($A10,'Campaign Performance'!$A:$A, 0))} -> 0 | Z10: {=INDEX('Campaign Performance'!F:F, MATCH($A10,'Campaign Performance'!$A:$A, 0))} -> 0 | AA10: {=INDEX('Campaign Performance'!G:G, MATCH($A10,'Campaign Performance'!$A:$A, 0))} -> 0 | AB10: {=INDEX('Campaign Performance'!H:H, MATCH($A10,'Campaign Performance'!$A:$A, 0))} -> 1 | AC10: =YEAR(TODAY()) - B10 -> 51 | AD10: =DATEDIF(I10,today(),"Y") -> 12 | AE10: =sum(J10:O10) -> 895.10034 | AF10: =sum(V10:Z10) -> 0 | AG10: =if(G10+H10 =0,"No kids",if(G10+H10 = 1,"Small family","Large family")) -> No kids | AH10: =if(E10< 30000, "Low income", if(E10 < 50000, "Mid income", "High income")) -> Mid income | AI10: =if(AB10 = 1, "Yes" , "No") -> Yes | AJ10: =if(AF10 = 0, "No Acceptance", if(AF10 = 1, "Low Acceptance", if(AF10 = 2,"Mid Acceptance","High Acceptance"))) -> No Acceptance | AK10: =IF(AH10 = "Low income", 1, if(AH10="Mid income", 2, 3)) -> 2 | AL10: =(AE10-min(AE:AE)) / (MAX(AE:AE)-min(AE:AE)) -> 0.045366176 | AM10: =(max(U:U) -U10)/max(U:U) -> 0.80808081 | AN10: =(Q10-min(Q:Q)) / (max(Q:Q)-min(Q:Q)) -> 0.11111111 | AO10: =(R10-min(R:R))/(max(R:R)-min(R:R)) -> 0 | AP10: =(AF10-min(AF:AF))/max(AF:AF)-min(AF:AF) -> 0 | AQ10: =(AK10-min(AK:AK))/(max(AK:AK)-min(AK:AK)) -> 0.5 | AR10: =0.3*AM10+0.25*AL10+0.15*AN10+0.1*AO10+0.1*AQ10+0.1*AP10 -> 0.32043245 | AS10: =RANK(AR10,AR:AR,FALSE) -> 788 | AT10: =(max(AS:AS)-AS10)/(max(AS:AS)-min(AS:AS)) -> 0.6485038 | AU10: =if(AT10<0.5,"Low", if(and(AT10>=0.5,AT10<0.74),"Mid","High")) -> Mid
A11: 5899 | B11: 1960 | C11: PhD | D11: Together | E11: 5648 | F11: =if(ISBLANK(E:E),MEDIAN(E:E), E:E) -> 5648 | G11: 0 | H11: 0 | I11: 2014-03-13 | J11: {=INDEX('Purchase Behaviour'!B:B,MATCH(A11,'Purchase Behaviour'!A:A, 0))} -> 19.036338 | K11: {=INDEX('Purchase Behaviour'!C:C, MATCH(A11,'Purchase Behaviour'!A:A, 0))} -> 33.662563 | L11: {=INDEX('Purchase Behaviour'!D:D, MATCH($A11,'Purchase Behaviour'!$A:$A, 0))} -> 18.069169 | M11: {=INDEX('Purchase Behaviour'!E:E, MATCH($A11,'Purchase Behaviour'!$A:$A, 0))} -> 36.599359 | N11: {=INDEX('Purchase Behaviour'!F:F, MATCH($A11,'Purchase Behaviour'!$A:$A, 0))} -> 26.299061 | O11: {=INDEX('Purchase Behaviour'!G:G, MATCH($A11,'Purchase Behaviour'!$A:$A, 0))} -> 26.586806 | P11: {=INDEX('Purchase Behaviour'!H:H, MATCH($A11,'Purchase Behaviour'!$A:$A, 0))} -> 1 | Q11: {=INDEX('Purchase Behaviour'!I:I, MATCH($A11,'Purchase Behaviour'!$A:$A, 0))} -> 1 | R11: {=INDEX('Purchase Behaviour'!J:J, MATCH($A11,'Purchase Behaviour'!$A:$A, 0))} -> 0 | S11: {=INDEX('Purchase Behaviour'!K:K, MATCH($A11,'Purchase Behaviour'!$A:$A, 0))} -> 0 | T11: {=INDEX('Purchase Behaviour'!L:L, MATCH($A11,'Purchase Behaviour'!$A:$A, 0))} -> 20 | U11: {=INDEX('Purchase Behaviour'!M:M, MATCH($A11,'Purchase Behaviour'!$A:$A, 0))} -> 68 | V11: {=INDEX('Campaign Performance'!B:B, MATCH(A11,'Campaign Performance'!A:A, 0))} -> 1 | W11: {=INDEX('Campaign Performance'!C:C, MATCH($A11,'Campaign Performance'!$A:$A, 0))} -> 0 | X11: {=INDEX('Campaign Performance'!D:D, MATCH($A11,'Campaign Performance'!$A:$A, 0))} -> 0 | Y11: {=INDEX('Campaign Performance'!E:E, MATCH($A11,'Campaign Performance'!$A:$A, 0))} -> 0 | Z11: {=INDEX('Campaign Performance'!F:F, MATCH($A11,'Campaign Performance'!$A:$A, 0))} -> 0 | AA11: {=INDEX('Campaign Performance'!G:G, MATCH($A11,'Campaign Performance'!$A:$A, 0))} -> 0 | AB11: {=INDEX('Campaign Performance'!H:H, MATCH($A11,'Campaign Performance'!$A:$A, 0))} -> 0 | AC11: =YEAR(TODAY()) - B11 -> 65 | AD11: =DATEDIF(I11,today(),"Y") -> 11 | AE11: =sum(J11:O11) -> 160.2533 | AF11: =sum(V11:Z11) -> 1 | AG11: =if(G11+H11 =0,"No kids",if(G11+H11 = 1,"Small family","Large family")) -> No kids | AH11: =if(E11< 30000, "Low income", if(E11 < 50000, "Mid income", "High income")) -> Low income | AI11: =if(AB11 = 1, "Yes" , "No") -> No | AJ11: =if(AF11 = 0, "No Acceptance", if(AF11 = 1, "Low Acceptance", if(AF11 = 2,"Mid Acceptance","High Acceptance"))) -> Low Acceptance | AK11: =IF(AH11 = "Low income", 1, if(AH11="Mid income", 2, 3)) -> 1 | AL11: =(AE11-min(AE:AE)) / (MAX(AE:AE)-min(AE:AE)) -> 0.008122083 | AM11: =(max(U:U) -U11)/max(U:U) -> 0.31313131 | AN11: =(Q11-min(Q:Q)) / (max(Q:Q)-min(Q:Q)) -> 0.037037037 | AO11: =(R11-min(R:R))/(max(R:R)-min(R:R)) -> 0 | AP11: =(AF11-min(AF:AF))/max(AF:AF)-min(AF:AF) -> 0.25 | AQ11: =(AK11-min(AK:AK))/(max(AK:AK)-min(AK:AK)) -> 0 | AR11: =0.3*AM11+0.25*AL11+0.15*AN11+0.1*AO11+0.1*AQ11+0.1*AP11 -> 0.12652547 | AS11: =RANK(AR11,AR:AR,FALSE) -> 1999 | AT11: =(max(AS:AS)-AS11)/(max(AS:AS)-min(AS:AS)) -> 0.10763734 | AU11: =if(AT11<0.5,"Low", if(and(AT11>=0.5,AT11<0.74),"Mid","High")) -> Low
A12: 1994 | B12: 1983 | C12: Graduation | D12: Married | F12: =if(ISBLANK(E:E),MEDIAN(E:E), E:E) -> 51381.5 | G12: 1 | H12: 0 | I12: 2013-11-15 | J12: {=INDEX('Purchase Behaviour'!B:B,MATCH(A12,'Purchase Behaviour'!A:A, 0))} | K12: {=INDEX('Purchase Behaviour'!C:C, MATCH(A12,'Purchase Behaviour'!A:A, 0))} | L12: {=INDEX('Purchase Behaviour'!D:D, MATCH($A12,'Purchase Behaviour'!$A:$A, 0))} | M12: {=INDEX('Purchase Behaviour'!E:E, MATCH($A12,'Purchase Behaviour'!$A:$A, 0))} | N12: {=INDEX('Purchase Behaviour'!F:F, MATCH($A12,'Purchase Behaviour'!$A:$A, 0))} | O12: {=INDEX('Purchase Behaviour'!G:G, MATCH($A12,'Purchase Behaviour'!$A:$A, 0))} | P12: {=INDEX('Purchase Behaviour'!H:H, MATCH($A12,'Purchase Behaviour'!$A:$A, 0))} -> 1 | Q12: {=INDEX('Purchase Behaviour'!I:I, MATCH($A12,'Purchase Behaviour'!$A:$A, 0))} -> 1 | R12: {=INDEX('Purchase Behaviour'!J:J, MATCH($A12,'Purchase Behaviour'!$A:$A, 0))} -> 0 | S12: {=INDEX('Purchase Behaviour'!K:K, MATCH($A12,'Purchase Behaviour'!$A:$A, 0))} -> 2 | T12: {=INDEX('Purchase Behaviour'!L:L, MATCH($A12,'Purchase Behaviour'!$A:$A, 0))} -> 7 | U12: {=INDEX('Purchase Behaviour'!M:M, MATCH($A12,'Purchase Behaviour'!$A:$A, 0))} -> 11 | V12: {=INDEX('Campaign Performance'!B:B, MATCH(A12,'Campaign Performance'!A:A, 0))} -> 0 | W12: {=INDEX('Campaign Performance'!C:C, MATCH($A12,'Campaign Performance'!$A:$A, 0))} -> 0 | X12: {=INDEX('Campaign Performance'!D:D, MATCH($A12,'Campaign Performance'!$A:$A, 0))} -> 0 | Y12: {=INDEX('Campaign Performance'!E:E, MATCH($A12,'Campaign Performance'!$A:$A, 0))} -> 0 | Z12: {=INDEX('Campaign Performance'!F:F, MATCH($A12,'Campaign Performance'!$A:$A, 0))} -> 0 | AA12: {=INDEX('Campaign Performance'!G:G, MATCH($A12,'Campaign Performance'!$A:$A, 0))} -> 1 | AB12: {=INDEX('Campaign Performance'!H:H, MATCH($A12,'Campaign Performance'!$A:$A, 0))} -> 0 | AC12: =YEAR(TODAY()) - B12 -> 42 | AD12: =DATEDIF(I12,today(),"Y") -> 12 | AE12: =sum(J12:O12) -> 0 | AF12: =sum(V12:Z12) -> 0 | AG12: =if(G12+H12 =0,"No kids",if(G12+H12 = 1,"Small family","Large family")) -> Small family | AH12: =if(E12< 30000, "Low income", if(E12 < 50000, "Mid income", "High income")) -> Low income | AI12: =if(AB12 = 1, "Yes" , "No") -> No | AJ12: =if(AF12 = 0, "No Acceptance", if(AF12 = 1, "Low Acceptance", if(AF12 = 2,"Mid Acceptance","High Acceptance"))) -> No Acceptance | AK12: =IF(AH12 = "Low income", 1, if(AH12="Mid income", 2, 3)) -> 1 | AL12: =(AE12-min(AE:AE)) / (MAX(AE:AE)-min(AE:AE)) -> 0 | AM12: =(max(U:U) -U12)/max(U:U) -> 0.88888889 | AN12: =(Q12-min(Q:Q)) / (max(Q:Q)-min(Q:Q)) -> 0.037037037 | AO12: =(R12-min(R:R))/(max(R:R)-min(R:R)) -> 0 | AP12: =(AF12-min(AF:AF))/max(AF:AF)-min(AF:AF) -> 0 | AQ12: =(AK12-min(AK:AK))/(max(AK:AK)-min(AK:AK)) -> 0 | AR12: =0.3*AM12+0.25*AL12+0.15*AN12+0.1*AO12+0.1*AQ12+0.1*AP12 -> 0.27222222 | AS12: =RANK(AR12,AR:AR,FALSE) -> 1160 | AT12: =(max(AS:AS)-AS12)/(max(AS:AS)-min(AS:AS)) -> 0.4823582 | AU12: =if(AT12<0.5,"Low", if(and(AT12>=0.5,AT12<0.74),"Mid","High")) -> Low
A13: 387 | B13: 1976 | C13: Basic | D13: Married | E13: 7500 | F13: =if(ISBLANK(E:E),MEDIAN(E:E), E:E) -> 7500 | G13: 1 | H13: 1 | I13: 2012-11-13 | J13: {=INDEX('Purchase Behaviour'!B:B,MATCH(A13,'Purchase Behaviour'!A:A, 0))} -> 44.935203 | K13: {=INDEX('Purchase Behaviour'!C:C, MATCH(A13,'Purchase Behaviour'!A:A, 0))} -> 19.520684 | L13: {=INDEX('Purchase Behaviour'!D:D, MATCH($A13,'Purchase Behaviour'!$A:$A, 0))} -> 34.811247 | M13: {=INDEX('Purchase Behaviour'!E:E, MATCH($A13,'Purchase Behaviour'!$A:$A, 0))} -> 26.460058 | N13: {=INDEX('Purchase Behaviour'!F:F, MATCH($A13,'Purchase Behaviour'!$A:$A, 0))} -> 45.877273 | O13: {=INDEX('Purchase Behaviour'!G:G, MATCH($A13,'Purchase Behaviour'!$A:$A, 0))} -> 48.693472 | P13: {=INDEX('Purchase Behaviour'!H:H, MATCH($A13,'Purchase Behaviour'!$A:$A, 0))} -> 1 | Q13: {=INDEX('Purchase Behaviour'!I:I, MATCH($A13,'Purchase Behaviour'!$A:$A, 0))} -> 2 | R13: {=INDEX('Purchase Behaviour'!J:J, MATCH($A13,'Purchase Behaviour'!$A:$A, 0))} -> 0 | S13: {=INDEX('Purchase Behaviour'!K:K, MATCH($A13,'Purchase Behaviour'!$A:$A, 0))} -> 3 | T13: {=INDEX('Purchase Behaviour'!L:L, MATCH($A13,'Purchase Behaviour'!$A:$A, 0))} -> 8 | U13: {=INDEX('Purchase Behaviour'!M:M, MATCH($A13,'Purchase Behaviour'!$A:$A, 0))} -> 59 | V13: {=INDEX('Campaign Performance'!B:B, MATCH(A13,'Campaign Performance'!A:A, 0))} -> 0 | W13: {=INDEX('Campaign Performance'!C:C, MATCH($A13,'Campaign Performance'!$A:$A, 0))} -> 0 | X13: {=INDEX('Campaign Performance'!D:D, MATCH($A13,'Campaign Performance'!$A:$A, 0))} -> 0 | Y13: {=INDEX('Campaign Performance'!E:E, MATCH($A13,'Campaign Performance'!$A:$A, 0))} -> 0 | Z13: {=INDEX('Campaign Performance'!F:F, MATCH($A13,'Campaign Performance'!$A:$A, 0))} -> 0 | AA13: {=INDEX('Campaign Performance'!G:G, MATCH($A13,'Campaign Performance'!$A:$A, 0))} -> 0 | AB13: {=INDEX('Campaign Performance'!H:H, MATCH($A13,'Campaign Performance'!$A:$A, 0))} -> 0 | AC13: =YEAR(TODAY()) - B13 -> 49 | AD13: =DATEDIF(I13,today(),"Y") -> 13 | AE13: =sum(J13:O13) -> 220.29794 | AF13: =sum(V13:Z13) -> 0 | AG13: =if(G13+H13 =0,"No kids",if(G13+H13 = 1,"Small family","Large family")) -> Large family | AH13: =if(E13< 30000, "Low income", if(E13 < 50000, "Mid income", "High income")) -> Low income | AI13: =if(AB13 = 1, "Yes" , "No") -> No | AJ13: =if(AF13 = 0, "No Acceptance", if(AF13 = 1, "Low Acceptance", if(AF13 = 2,"Mid Acceptance","High Acceptance"))) -> No Acceptance | AK13: =IF(AH13 = "Low income", 1, if(AH13="Mid income", 2, 3)) -> 1 | AL13: =(AE13-min(AE:AE)) / (MAX(AE:AE)-min(AE:AE)) -> 0.011165312 | AM13: =(max(U:U) -U13)/max(U:U) -> 0.4040404 | AN13: =(Q13-min(Q:Q)) / (max(Q:Q)-min(Q:Q)) -> 0.074074074 | AO13: =(R13-min(R:R))/(max(R:R)-min(R:R)) -> 0 | AP13: =(AF13-min(AF:AF))/max(AF:AF)-min(AF:AF) -> 0 | AQ13: =(AK13-min(AK:AK))/(max(AK:AK)-min(AK:AK)) -> 0 | AR13: =0.3*AM13+0.25*AL13+0.15*AN13+0.1*AO13+0.1*AQ13+0.1*AP13 -> 0.13511456 | AS13: =RANK(AR13,AR:AR,FALSE) -> 1971 | AT13: =(max(AS:AS)-AS13)/(max(AS:AS)-min(AS:AS)) -> 0.12014292 | AU13: =if(AT13<0.5,"Low", if(and(AT13>=0.5,AT13<0.74),"Mid","High")) -> Low
A14: 2125 | B14: 1960 | C14: Graduation | D14: Divorced | E14: 63033 | F14: =if(ISBLANK(E:E),MEDIAN(E:E), E:E) -> 63033 | G14: 0 | H14: 0 | I14: 2013-11-15 | J14: {=INDEX('Purchase Behaviour'!B:B,MATCH(A14,'Purchase Behaviour'!A:A, 0))} -> 320.8153 | K14: {=INDEX('Purchase Behaviour'!C:C, MATCH(A14,'Purchase Behaviour'!A:A, 0))} -> 317.64118 | L14: {=INDEX('Purchase Behaviour'!D:D, MATCH($A14,'Purchase Behaviour'!$A:$A, 0))} -> 369.57278 | M14: {=INDEX('Purchase Behaviour'!E:E, MATCH($A14,'Purchase Behaviour'!$A:$A, 0))} -> 409.8135 | N14: {=INDEX('Purchase Behaviour'!F:F, MATCH($A14,'Purchase Behaviour'!$A:$A, 0))} -> 305.21025 | O14: {=INDEX('Purchase Behaviour'!G:G, MATCH($A14,'Purchase Behaviour'!$A:$A, 0))} -> 253.38304 | P14: {=INDEX('Purchase Behaviour'!H:H, MATCH($A14,'Purchase Behaviour'!$A:$A, 0))} -> 1 | Q14: {=INDEX('Purchase Behaviour'!I:I, MATCH($A14,'Purchase Behaviour'!$A:$A, 0))} -> 3 | R14: {=INDEX('Purchase Behaviour'!J:J, MATCH($A14,'Purchase Behaviour'!$A:$A, 0))} -> 4 | S14: {=INDEX('Purchase Behaviour'!K:K, MATCH($A14,'Purchase Behaviour'!$A:$A, 0))} -> 8 | T14: {=INDEX('Purchase Behaviour'!L:L, MATCH($A14,'Purchase Behaviour'!$A:$A, 0))} -> 2 | U14: {=INDEX('Purchase Behaviour'!M:M, MATCH($A14,'Purchase Behaviour'!$A:$A, 0))} -> 82 | V14: {=INDEX('Campaign Performance'!B:B, MATCH(A14,'Campaign Performance'!A:A, 0))} -> 0 | W14: {=INDEX('Campaign Performance'!C:C, MATCH($A14,'Campaign Performance'!$A:$A, 0))} -> 0 | X14: {=INDEX('Campaign Performance'!D:D, MATCH($A14,'Campaign Performance'!$A:$A, 0))} -> 0 | Y14: {=INDEX('Campaign Performance'!E:E, MATCH($A14,'Campaign Performance'!$A:$A, 0))} -> 0 | Z14: {=INDEX('Campaign Performance'!F:F, MATCH($A14,'Campaign Performance'!$A:$A, 0))} -> 0 | AA14: {=INDEX('Campaign Performance'!G:G, MATCH($A14,'Campaign Performance'!$A:$A, 0))} -> 1 | AB14: {=INDEX('Campaign Performance'!H:H, MATCH($A14,'Campaign Performance'!$A:$A, 0))} -> 0 | AC14: =YEAR(TODAY()) - B14 -> 65 | AD14: =DATEDIF(I14,today(),"Y") -> 12 | AE14: =sum(J14:O14) -> 1976.436 | AF14: =sum(V14:Z14) -> 0 | AG14: =if(G14+H14 =0,"No kids",if(G14+H14 = 1,"Small family","Large family")) -> No kids | AH14: =if(E14< 30000, "Low income", if(E14 < 50000, "Mid income", "High income")) -> High income | AI14: =if(AB14 = 1, "Yes" , "No") -> No | AJ14: =if(AF14 = 0, "No Acceptance", if(AF14 = 1, "Low Acceptance", if(AF14 = 2,"Mid Acceptance","High Acceptance"))) -> No Acceptance | AK14: =IF(AH14 = "Low income", 1, if(AH14="Mid income", 2, 3)) -> 3 | AL14: =(AE14-min(AE:AE)) / (MAX(AE:AE)-min(AE:AE)) -> 0.10017128 | AM14: =(max(U:U) -U14)/max(U:U) -> 0.17171717 | AN14: =(Q14-min(Q:Q)) / (max(Q:Q)-min(Q:Q)) -> 0.11111111 | AO14: =(R14-min(R:R))/(max(R:R)-min(R:R)) -> 0.14285714 | AP14: =(AF14-min(AF:AF))/max(AF:AF)-min(AF:AF) -> 0 | AQ14: =(AK14-min(AK:AK))/(max(AK:AK)-min(AK:AK)) -> 1 | AR14: =0.3*AM14+0.25*AL14+0.15*AN14+0.1*AO14+0.1*AQ14+0.1*AP14 -> 0.20751035 | AS14: =RANK(AR14,AR:AR,FALSE) -> 1611 | AT14: =(max(AS:AS)-AS14)/(max(AS:AS)-min(AS:AS)) -> 0.28092899 | AU14: =if(AT14<0.5,"Low", if(and(AT14>=0.5,AT14<0.74),"Mid","High")) -> Low
A15: 8180 | B15: 1960 | C15: Master | D15: Divorced | E15: 59354 | F15: =if(ISBLANK(E:E),MEDIAN(E:E), E:E) -> 59354 | G15: 0 | H15: 0 | I15: 2013-11-15 | J15: {=INDEX('Purchase Behaviour'!B:B,MATCH(A15,'Purchase Behaviour'!A:A, 0))} -> 342.83015 | K15: {=INDEX('Purchase Behaviour'!C:C, MATCH(A15,'Purchase Behaviour'!A:A, 0))} -> 115.08103 | L15: {=INDEX('Purchase Behaviour'!D:D, MATCH($A15,'Purchase Behaviour'!$A:$A, 0))} -> 366.67607 | M15: {=INDEX('Purchase Behaviour'!E:E, MATCH($A15,'Purchase Behaviour'!$A:$A, 0))} -> 219.46236 | N15: {=INDEX('Purchase Behaviour'!F:F, MATCH($A15,'Purchase Behaviour'!$A:$A, 0))} -> 262.17305 | O15: {=INDEX('Purchase Behaviour'!G:G, MATCH($A15,'Purchase Behaviour'!$A:$A, 0))} -> 367.25769 | P15: {=INDEX('Purchase Behaviour'!H:H, MATCH($A15,'Purchase Behaviour'!$A:$A, 0))} -> 3 | Q15: {=INDEX('Purchase Behaviour'!I:I, MATCH($A15,'Purchase Behaviour'!$A:$A, 0))} -> 6 | R15: {=INDEX('Purchase Behaviour'!J:J, MATCH($A15,'Purchase Behaviour'!$A:$A, 0))} -> 1 | S15: {=INDEX('Purchase Behaviour'!K:K, MATCH($A15,'Purchase Behaviour'!$A:$A, 0))} -> 5 | T15: {=INDEX('Purchase Behaviour'!L:L, MATCH($A15,'Purchase Behaviour'!$A:$A, 0))} -> 6 | U15: {=INDEX('Purchase Behaviour'!M:M, MATCH($A15,'Purchase Behaviour'!$A:$A, 0))} -> 53 | V15: {=INDEX('Campaign Performance'!B:B, MATCH(A15,'Campaign Performance'!A:A, 0))} -> 0 | W15: {=INDEX('Campaign Performance'!C:C, MATCH($A15,'Campaign Performance'!$A:$A, 0))} -> 0 | X15: {=INDEX('Campaign Performance'!D:D, MATCH($A15,'Campaign Performance'!$A:$A, 0))} -> 0 | Y15: {=INDEX('Campaign Performance'!E:E, MATCH($A15,'Campaign Performance'!$A:$A, 0))} -> 0 | Z15: {=INDEX('Campaign Performance'!F:F, MATCH($A15,'Campaign Performance'!$A:$A, 0))} -> 0 | AA15: {=INDEX('Campaign Performance'!G:G, MATCH($A15,'Campaign Performance'!$A:$A, 0))} -> 0 | AB15: {=INDEX('Campaign Performance'!H:H, MATCH($A15,'Campaign Performance'!$A:$A, 0))} -> 0 | AC15: =YEAR(TODAY()) - B15 -> 65 | AD15: =DATEDIF(I15,today(),"Y") -> 12 | AE15: =sum(J15:O15) -> 1673.4804 | AF15: =sum(V15:Z15) -> 0 | AG15: =if(G15+H15 =0,"No kids",if(G15+H15 = 1,"Small family","Large family")) -> No kids | AH15: =if(E15< 30000, "Low income", if(E15 < 50000, "Mid income", "High income")) -> High income | AI15: =if(AB15 = 1, "Yes" , "No") -> No | AJ15: =if(AF15 = 0, "No Acceptance", if(AF15 = 1, "Low Acceptance", if(AF15 = 2,"Mid Acceptance","High Acceptance"))) -> No Acceptance | AK15: =IF(AH15 = "Low income", 1, if(AH15="Mid income", 2, 3)) -> 3 | AL15: =(AE15-min(AE:AE)) / (MAX(AE:AE)-min(AE:AE)) -> 0.084816641 | AM15: =(max(U:U) -U15)/max(U:U) -> 0.46464646 | AN15: =(Q15-min(Q:Q)) / (max(Q:Q)-min(Q:Q)) -> 0.22222222 | AO15: =(R15-min(R:R))/(max(R:R)-min(R:R)) -> 0.035714286 | AP15: =(AF15-min(AF:AF))/max(AF:AF)-min(AF:AF) -> 0 | AQ15: =(AK15-min(AK:AK))/(max(AK:AK)-min(AK:AK)) -> 1 | AR15: =0.3*AM15+0.25*AL15+0.15*AN15+0.1*AO15+0.1*AQ15+0.1*AP15 -> 0.29750286 | AS15: =RANK(AR15,AR:AR,FALSE) -> 974 | AT15: =(max(AS:AS)-AS15)/(max(AS:AS)-min(AS:AS)) -> 0.565431 | AU15: =if(AT15<0.5,"Low", if(and(AT15>=0.5,AT15<0.74),"Mid","High")) -> Mid
A16: 2569 | B16: 1987 | C16: Graduation | D16: Married | E16: 17323 | F16: =if(ISBLANK(E:E),MEDIAN(E:E), E:E) -> 17323 | G16: 0 | H16: 1 | I16: 2012-10-10 | J16: {=INDEX('Purchase Behaviour'!B:B,MATCH(A16,'Purchase Behaviour'!A:A, 0))} -> 71.868284 | K16: {=INDEX('Purchase Behaviour'!C:C, MATCH(A16,'Purchase Behaviour'!A:A, 0))} -> 100.06182 | L16: {=INDEX('Purchase Behaviour'!D:D, MATCH($A16,'Purchase Behaviour'!$A:$A, 0))} -> 113.09868 | M16: {=INDEX('Purchase Behaviour'!E:E, MATCH($A16,'Purchase Behaviour'!$A:$A, 0))} -> 85.808117 | N16: {=INDEX('Purchase Behaviour'!F:F, MATCH($A16,'Purchase Behaviour'!$A:$A, 0))} -> 91.150581 | O16: {=INDEX('Purchase Behaviour'!G:G, MATCH($A16,'Purchase Behaviour'!$A:$A, 0))} -> 79.721533 | P16: {=INDEX('Purchase Behaviour'!H:H, MATCH($A16,'Purchase Behaviour'!$A:$A, 0))} -> 1 | Q16: {=INDEX('Purchase Behaviour'!I:I, MATCH($A16,'Purchase Behaviour'!$A:$A, 0))} -> 1 | R16: {=INDEX('Purchase Behaviour'!J:J, MATCH($A16,'Purchase Behaviour'!$A:$A, 0))} -> 0 | S16: {=INDEX('Purchase Behaviour'!K:K, MATCH($A16,'Purchase Behaviour'!$A:$A, 0))} -> 3 | T16: {=INDEX('Purchase Behaviour'!L:L, MATCH($A16,'Purchase Behaviour'!$A:$A, 0))} -> 8 | U16: {=INDEX('Purchase Behaviour'!M:M, MATCH($A16,'Purchase Behaviour'!$A:$A, 0))} -> 38 | V16: {=INDEX('Campaign Performance'!B:B, MATCH(A16,'Campaign Performance'!A:A, 0))} -> 0 | W16: {=INDEX('Campaign Performance'!C:C, MATCH($A16,'Campaign Performance'!$A:$A, 0))} -> 0 | X16: {=INDEX('Campaign Performance'!D:D, MATCH($A16,'Campaign Performance'!$A:$A, 0))} -> 0 | Y16: {=INDEX('Campaign Performance'!E:E, MATCH($A16,'Campaign Performance'!$A:$A, 0))} -> 0 | Z16: {=INDEX('Campaign Performance'!F:F, MATCH($A16,'Campaign Performance'!$A:$A, 0))} -> 0 | AA16: {=INDEX('Campaign Performance'!G:G, MATCH($A16,'Campaign Performance'!$A:$A, 0))} -> 0 | AB16: {=INDEX('Campaign Performance'!H:H, MATCH($A16,'Campaign Performance'!$A:$A, 0))} -> 0 | AC16: =YEAR(TODAY()) - B16 -> 38 | AD16: =DATEDIF(I16,today(),"Y") -> 13 | AE16: =sum(J16:O16) -> 541.70902 | AF16: =sum(V16:Z16) -> 0 | AG16: =if(G16+H16 =0,"No kids",if(G16+H16 = 1,"Small family","Large family")) -> Small family | AH16: =if(E16< 30000, "Low income", if(E16 < 50000, "Mid income", "High income")) -> Low income | AI16: =if(AB16 = 1, "Yes" , "No") -> No | AJ16: =if(AF16 = 0, "No Acceptance", if(AF16 = 1, "Low Acceptance", if(AF16 = 2,"Mid Acceptance","High Acceptance"))) -> No Acceptance | AK16: =IF(AH16 = "Low income", 1, if(AH16="Mid income", 2, 3)) -> 1 | AL16: =(AE16-min(AE:AE)) / (MAX(AE:AE)-min(AE:AE)) -> 0.027455321 | AM16: =(max(U:U) -U16)/max(U:U) -> 0.61616162 | AN16: =(Q16-min(Q:Q)) / (max(Q:Q)-min(Q:Q)) -> 0.037037037 | AO16: =(R16-min(R:R))/(max(R:R)-min(R:R)) -> 0 | AP16: =(AF16-min(AF:AF))/max(AF:AF)-min(AF:AF) -> 0 | AQ16: =(AK16-min(AK:AK))/(max(AK:AK)-min(AK:AK)) -> 0 | AR16: =0.3*AM16+0.25*AL16+0.15*AN16+0.1*AO16+0.1*AQ16+0.1*AP16 -> 0.19726787 | AS16: =RANK(AR16,AR:AR,FALSE) -> 1683 | AT16: =(max(AS:AS)-AS16)/(max(AS:AS)-min(AS:AS)) -> 0.24877177 | AU16: =if(AT16<0.5,"Low", if(and(AT16>=0.5,AT16<0.74),"Mid","High")) -> Low
A17: 2114 | B17: 1960 | C17: PhD | D17: Single | E17: 82800 | F17: =if(ISBLANK(E:E),MEDIAN(E:E), E:E) -> 82800 | G17: 0 | H17: 0 | I17: 2012-11-24 | J17: {=INDEX('Purchase Behaviour'!B:B,MATCH(A17,'Purchase Behaviour'!A:A, 0))} -> 410.84881 | K17: {=INDEX('Purchase Behaviour'!C:C, MATCH(A17,'Purchase Behaviour'!A:A, 0))} -> 254.6533 | L17: {=INDEX('Purchase Behaviour'!D:D, MATCH($A17,'Purchase Behaviour'!$A:$A, 0))} -> 358.95245 | M17: {=INDEX('Purchase Behaviour'!E:E, MATCH($A17,'Purchase Behaviour'!$A:$A, 0))} -> 232.87208 | N17: {=INDEX('Purchase Behaviour'!F:F, MATCH($A17,'Purchase Behaviour'!$A:$A, 0))} -> 282.24577 | O17: {=INDEX('Purchase Behaviour'!G:G, MATCH($A17,'Purchase Behaviour'!$A:$A, 0))} -> 142.25563 | P17: {=INDEX('Purchase Behaviour'!H:H, MATCH($A17,'Purchase Behaviour'!$A:$A, 0))} -> 1 | Q17: {=INDEX('Purchase Behaviour'!I:I, MATCH($A17,'Purchase Behaviour'!$A:$A, 0))} -> 7 | R17: {=INDEX('Purchase Behaviour'!J:J, MATCH($A17,'Purchase Behaviour'!$A:$A, 0))} -> 6 | S17: {=INDEX('Purchase Behaviour'!K:K, MATCH($A17,'Purchase Behaviour'!$A:$A, 0))} -> 12 | T17: {=INDEX('Purchase Behaviour'!L:L, MATCH($A17,'Purchase Behaviour'!$A:$A, 0))} -> 3 | U17: {=INDEX('Purchase Behaviour'!M:M, MATCH($A17,'Purchase Behaviour'!$A:$A, 0))} -> 23 | V17: {=INDEX('Campaign Performance'!B:B, MATCH(A17,'Campaign Performance'!A:A, 0))} -> 0 | W17: {=INDEX('Campaign Performance'!C:C, MATCH($A17,'Campaign Performance'!$A:$A, 0))} -> 0 | X17: {=INDEX('Campaign Performance'!D:D, MATCH($A17,'Campaign Performance'!$A:$A, 0))} -> 1 | Y17: {=INDEX('Campaign Performance'!E:E, MATCH($A17,'Campaign Performance'!$A:$A, 0))} -> 1 | Z17: {=INDEX('Campaign Performance'!F:F, MATCH($A17,'Campaign Performance'!$A:$A, 0))} -> 0 | AA17: {=INDEX('Campaign Performance'!G:G, MATCH($A17,'Campaign Performance'!$A:$A, 0))} -> 0 | AB17: {=INDEX('Campaign Performance'!H:H, MATCH($A17,'Campaign Performance'!$A:$A, 0))} -> 1 | AC17: =YEAR(TODAY()) - B17 -> 65 | AD17: =DATEDIF(I17,today(),"Y") -> 12 | AE17: =sum(J17:O17) -> 1681.828 | AF17: =sum(V17:Z17) -> 2 | AG17: =if(G17+H17 =0,"No kids",if(G17+H17 = 1,"Small family","Large family")) -> No kids | AH17: =if(E17< 30000, "Low income", if(E17 < 50000, "Mid income", "High income")) -> High income | AI17: =if(AB17 = 1, "Yes" , "No") -> Yes | AJ17: =if(AF17 = 0, "No Acceptance", if(AF17 = 1, "Low Acceptance", if(AF17 = 2,"Mid Acceptance","High Acceptance"))) -> Mid Acceptance | AK17: =IF(AH17 = "Low income", 1, if(AH17="Mid income", 2, 3)) -> 3 | AL17: =(AE17-min(AE:AE)) / (MAX(AE:AE)-min(AE:AE)) -> 0.085239725 | AM17: =(max(U:U) -U17)/max(U:U) -> 0.76767677 | AN17: =(Q17-min(Q:Q)) / (max(Q:Q)-min(Q:Q)) -> 0.25925926 | AO17: =(R17-min(R:R))/(max(R:R)-min(R:R)) -> 0.21428571 | AP17: =(AF17-min(AF:AF))/max(AF:AF)-min(AF:AF) -> 0.5 | AQ17: =(AK17-min(AK:AK))/(max(AK:AK)-min(AK:AK)) -> 1 | AR17: =0.3*AM17+0.25*AL17+0.15*AN17+0.1*AO17+0.1*AQ17+0.1*AP17 -> 0.46193042 | AS17: =RANK(AR17,AR:AR,FALSE) -> 114 | AT17: =(max(AS:AS)-AS17)/(max(AS:AS)-min(AS:AS)) -> 0.94953104 | AU17: =if(AT17<0.5,"Low", if(and(AT17>=0.5,AT17<0.74),"Mid","High")) -> High
A18: 9736 | B18: 1980 | C18: Graduation | D18: Married | E18: 41850 | F18: =if(ISBLANK(E:E),MEDIAN(E:E), E:E) -> 41850 | G18: 0 | H18: 0 | I18: 2012-12-24 | J18: {=INDEX('Purchase Behaviour'!B:B,MATCH(A18,'Purchase Behaviour'!A:A, 0))} -> 217.16227 | K18: {=INDEX('Purchase Behaviour'!C:C, MATCH(A18,'Purchase Behaviour'!A:A, 0))} -> 308.64751 | L18: {=INDEX('Purchase Behaviour'!D:D, MATCH($A18,'Purchase Behaviour'!$A:$A, 0))} -> 171.02255 | M18: {=INDEX('Purchase Behaviour'!E:E, MATCH($A18,'Purchase Behaviour'!$A:$A, 0))} -> 262.09546 | N18: {=INDEX('Purchase Behaviour'!F:F, MATCH($A18,'Purchase Behaviour'!$A:$A, 0))} -> 272.38408 | O18: {=INDEX('Purchase Behaviour'!G:G, MATCH($A18,'Purchase Behaviour'!$A:$A, 0))} -> 123.40914 | P18: {=INDEX('Purchase Behaviour'!H:H, MATCH($A18,'Purchase Behaviour'!$A:$A, 0))} -> 3 | Q18: {=INDEX('Purchase Behaviour'!I:I, MATCH($A18,'Purchase Behaviour'!$A:$A, 0))} -> 3 | R18: {=INDEX('Purchase Behaviour'!J:J, MATCH($A18,'Purchase Behaviour'!$A:$A, 0))} -> 0 | S18: {=INDEX('Purchase Behaviour'!K:K, MATCH($A18,'Purchase Behaviour'!$A:$A, 0))} -> 3 | T18: {=INDEX('Purchase Behaviour'!L:L, MATCH($A18,'Purchase Behaviour'!$A:$A, 0))} -> 8 | U18: {=INDEX('Purchase Behaviour'!M:M, MATCH($A18,'Purchase Behaviour'!$A:$A, 0))} -> 51 | V18: {=INDEX('Campaign Performance'!B:B, MATCH(A18,'Campaign Performance'!A:A, 0))} -> 0 | W18: {=INDEX('Campaign Performance'!C:C, MATCH($A18,'Campaign Performance'!$A:$A, 0))} -> 0 | X18: {=INDEX('Campaign Performance'!D:D, MATCH($A18,'Campaign Performance'!$A:$A, 0))} -> 0 | Y18: {=INDEX('Campaign Performance'!E:E, MATCH($A18,'Campaign Performance'!$A:$A, 0))} -> 0 | Z18: {=INDEX('Campaign Performance'!F:F, MATCH($A18,'Campaign Performance'!$A:$A, 0))} -> 0 | AA18: {=INDEX('Campaign Performance'!G:G, MATCH($A18,'Campaign Performance'!$A:$A, 0))} -> 0 | AB18: {=INDEX('Campaign Performance'!H:H, MATCH($A18,'Campaign Performance'!$A:$A, 0))} -> 0 | AC18: =YEAR(TODAY()) - B18 -> 45 | AD18: =DATEDIF(I18,today(),"Y") -> 12 | AE18: =sum(J18:O18) -> 1354.721 | AF18: =sum(V18:Z18) -> 0 | AG18: =if(G18+H18 =0,"No kids",if(G18+H18 = 1,"Small family","Large family")) -> No kids | AH18: =if(E18< 30000, "Low income", if(E18 < 50000, "Mid income", "High income")) -> Mid income | AI18: =if(AB18 = 1, "Yes" , "No") -> No | AJ18: =if(AF18 = 0, "No Acceptance", if(AF18 = 1, "Low Acceptance", if(AF18 = 2,"Mid Acceptance","High Acceptance"))) -> No Acceptance | AK18: =IF(AH18 = "Low income", 1, if(AH18="Mid income", 2, 3)) -> 2 | AL18: =(AE18-min(AE:AE)) / (MAX(AE:AE)-min(AE:AE)) -> 0.06866103 | AM18: =(max(U:U) -U18)/max(U:U) -> 0.48484848 | AN18: =(Q18-min(Q:Q)) / (max(Q:Q)-min(Q:Q)) -> 0.11111111 | AO18: =(R18-min(R:R))/(max(R:R)-min(R:R)) -> 0 | AP18: =(AF18-min(AF:AF))/max(AF:AF)-min(AF:AF) -> 0 | AQ18: =(AK18-min(AK:AK))/(max(AK:AK)-min(AK:AK)) -> 0.5 | AR18: =0.3*AM18+0.25*AL18+0.15*AN18+0.1*AO18+0.1*AQ18+0.1*AP18 -> 0.22928647 | AS18: =RANK(AR18,AR:AR,FALSE) -> 1461 | AT18: =(max(AS:AS)-AS18)/(max(AS:AS)-min(AS:AS)) -> 0.34792318 | AU18: =if(AT18<0.5,"Low", if(and(AT18>=0.5,AT18<0.74),"Mid","High")) -> Low
A19: 4939 | B19: 1960 | C19: Graduation | D19: Together | E19: 37760 | F19: =if(ISBLANK(E:E),MEDIAN(E:E), E:E) -> 37760 | G19: 0 | H19: 0 | I19: 2012-08-31 | J19: {=INDEX('Purchase Behaviour'!B:B,MATCH(A19,'Purchase Behaviour'!A:A, 0))} -> 123.79896 | K19: {=INDEX('Purchase Behaviour'!C:C, MATCH(A19,'Purchase Behaviour'!A:A, 0))} -> 237.96473 | L19: {=INDEX('Purchase Behaviour'!D:D, MATCH($A19,'Purchase Behaviour'!$A:$A, 0))} -> 175.34042 | M19: {=INDEX('Purchase Behaviour'!E:E, MATCH($A19,'Purchase Behaviour'!$A:$A, 0))} -> 106.04931 | N19: {=INDEX('Purchase Behaviour'!F:F, MATCH($A19,'Purchase Behaviour'!$A:$A, 0))} -> 143.8578 | O19: {=INDEX('Purchase Behaviour'!G:G, MATCH($A19,'Purchase Behaviour'!$A:$A, 0))} -> 204.94302 | P19: {=INDEX('Purchase Behaviour'!H:H, MATCH($A19,'Purchase Behaviour'!$A:$A, 0))} -> 2 | Q19: {=INDEX('Purchase Behaviour'!I:I, MATCH($A19,'Purchase Behaviour'!$A:$A, 0))} -> 4 | R19: {=INDEX('Purchase Behaviour'!J:J, MATCH($A19,'Purchase Behaviour'!$A:$A, 0))} -> 1 | S19: {=INDEX('Purchase Behaviour'!K:K, MATCH($A19,'Purchase Behaviour'!$A:$A, 0))} -> 6 | T19: {=INDEX('Purchase Behaviour'!L:L, MATCH($A19,'Purchase Behaviour'!$A:$A, 0))} -> 7 | U19: {=INDEX('Purchase Behaviour'!M:M, MATCH($A19,'Purchase Behaviour'!$A:$A, 0))} -> 20 | V19: {=INDEX('Campaign Performance'!B:B, MATCH(A19,'Campaign Performance'!A:A, 0))} -> 0 | W19: {=INDEX('Campaign Performance'!C:C, MATCH($A19,'Campaign Performance'!$A:$A, 0))} -> 0 | X19: {=INDEX('Campaign Performance'!D:D, MATCH($A19,'Campaign Performance'!$A:$A, 0))} -> 0 | Y19: {=INDEX('Campaign Performance'!E:E, MATCH($A19,'Campaign Performance'!$A:$A, 0))} -> 0 | Z19: {=INDEX('Campaign Performance'!F:F, MATCH($A19,'Campaign Performance'!$A:$A, 0))} -> 0 | AA19: {=INDEX('Campaign Performance'!G:G, MATCH($A19,'Campaign Performance'!$A:$A, 0))} -> 0 | AB19: {=INDEX('Campaign Performance'!H:H, MATCH($A19,'Campaign Performance'!$A:$A, 0))} -> 0 | AC19: =YEAR(TODAY()) - B19 -> 65 | AD19: =DATEDIF(I19,today(),"Y") -> 13 | AE19: =sum(J19:O19) -> 991.95424 | AF19: =sum(V19:Z19) -> 0 | AG19: =if(G19+H19 =0,"No kids",if(G19+H19 = 1,"Small family","Large family")) -> No kids | AH19: =if(E19< 30000, "Low income", if(E19 < 50000, "Mid income", "High income")) -> Mid income | AI19: =if(AB19 = 1, "Yes" , "No") -> No | AJ19: =if(AF19 = 0, "No Acceptance", if(AF19 = 1, "Low Acceptance", if(AF19 = 2,"Mid Acceptance","High Acceptance"))) -> No Acceptance | AK19: =IF(AH19 = "Low income", 1, if(AH19="Mid income", 2, 3)) -> 2 | AL19: =(AE19-min(AE:AE)) / (MAX(AE:AE)-min(AE:AE)) -> 0.050275001 | AM19: =(max(U:U) -U19)/max(U:U) -> 0.7979798 | AN19: =(Q19-min(Q:Q)) / (max(Q:Q)-min(Q:Q)) -> 0.14814815 | AO19: =(R19-min(R:R))/(max(R:R)-min(R:R)) -> 0.035714286 | AP19: =(AF19-min(AF:AF))/max(AF:AF)-min(AF:AF) -> 0 | AQ19: =(AK19-min(AK:AK))/(max(AK:AK)-min(AK:AK)) -> 0.5 | AR19: =0.3*AM19+0.25*AL19+0.15*AN19+0.1*AO19+0.1*AQ19+0.1*AP19 -> 0.32775634 | AS19: =RANK(AR19,AR:AR,FALSE) -> 740 | AT19: =(max(AS:AS)-AS19)/(max(AS:AS)-min(AS:AS)) -> 0.66994194 | AU19: =if(AT19<0.5,"Low", if(and(AT19>=0.5,AT19<0.74),"Mid","High")) -> Mid
A20: 6565 | B20: 1960 | C20: Master | D20: Married | E20: 76995 | F20: =if(ISBLANK(E:E),MEDIAN(E:E), E:E) -> 76995 | G20: 0 | H20: 0 | I20: 2013-03-28 | J20: {=INDEX('Purchase Behaviour'!B:B,MATCH(A20,'Purchase Behaviour'!A:A, 0))} -> 274.81671 | K20: {=INDEX('Purchase Behaviour'!C:C, MATCH(A20,'Purchase Behaviour'!A:A, 0))} -> 41.31725 | L20: {=INDEX('Purchase Behaviour'!D:D, MATCH($A20,'Purchase Behaviour'!$A:$A, 0))} -> 330.45332 | M20: {=INDEX('Purchase Behaviour'!E:E, MATCH($A20,'Purchase Behaviour'!$A:$A, 0))} -> 340.00503 | N20: {=INDEX('Purchase Behaviour'!F:F, MATCH($A20,'Purchase Behaviour'!$A:$A, 0))} -> 369.50424 | O20: {=INDEX('Purchase Behaviour'!G:G, MATCH($A20,'Purchase Behaviour'!$A:$A, 0))} -> 516.8304 | P20: {=INDEX('Purchase Behaviour'!H:H, MATCH($A20,'Purchase Behaviour'!$A:$A, 0))} -> 2 | Q20: {=INDEX('Purchase Behaviour'!I:I, MATCH($A20,'Purchase Behaviour'!$A:$A, 0))} -> 11 | R20: {=INDEX('Purchase Behaviour'!J:J, MATCH($A20,'Purchase Behaviour'!$A:$A, 0))} -> 4 | S20: {=INDEX('Purchase Behaviour'!K:K, MATCH($A20,'Purchase Behaviour'!$A:$A, 0))} -> 9 | T20: {=INDEX('Purchase Behaviour'!L:L, MATCH($A20,'Purchase Behaviour'!$A:$A, 0))} -> 5 | U20: {=INDEX('Purchase Behaviour'!M:M, MATCH($A20,'Purchase Behaviour'!$A:$A, 0))} -> 91 | V20: {=INDEX('Campaign Performance'!B:B, MATCH(A20,'Campaign Performance'!A:A, 0))} -> 0 | W20: {=INDEX('Campaign Performance'!C:C, MATCH($A20,'Campaign Performance'!$A:$A, 0))} -> 0 | X20: {=INDEX('Campaign Performance'!D:D, MATCH($A20,'Campaign Performance'!$A:$A, 0))} -> 0 | Y20: {=INDEX('Campaign Performance'!E:E, MATCH($A20,'Campaign Performance'!$A:$A, 0))} -> 1 | Z20: {=INDEX('Campaign Performance'!F:F, MATCH($A20,'Campaign Performance'!$A:$A, 0))} -> 0 | AA20: {=INDEX('Campaign Performance'!G:G, MATCH($A20,'Campaign Performance'!$A:$A, 0))} -> 0 | AB20: {=INDEX('Campaign Performance'!H:H, MATCH($A20,'Campaign Performance'!$A:$A, 0))} -> 0 | AC20: =YEAR(TODAY()) - B20 -> 65 | AD20: =DATEDIF(I20,today(),"Y") -> 12 | AE20: =sum(J20:O20) -> 1872.927 | AF20: =sum(V20:Z20) -> 1 | AG20: =if(G20+H20 =0,"No kids",if(G20+H20 = 1,"Small family","Large family")) -> No kids | AH20: =if(E20< 30000, "Low income", if(E20 < 50000, "Mid income", "High income")) -> High income | AI20: =if(AB20 = 1, "Yes" , "No") -> No | AJ20: =if(AF20 = 0, "No Acceptance", if(AF20 = 1, "Low Acceptance", if(AF20 = 2,"Mid Acceptance","High Acceptance"))) -> Low Acceptance | AK20: =IF(AH20 = "Low income", 1, if(AH20="Mid income", 2, 3)) -> 3 | AL20: =(AE20-min(AE:AE)) / (MAX(AE:AE)-min(AE:AE)) -> 0.09492515 | AM20: =(max(U:U) -U20)/max(U:U) -> 0.080808081 | AN20: =(Q20-min(Q:Q)) / (max(Q:Q)-min(Q:Q)) -> 0.40740741 | AO20: =(R20-min(R:R))/(max(R:R)-min(R:R)) -> 0.14285714 | AP20: =(AF20-min(AF:AF))/max(AF:AF)-min(AF:AF) -> 0.25 | AQ20: =(AK20-min(AK:AK))/(max(AK:AK)-min(AK:AK)) -> 1 | AR20: =0.3*AM20+0.25*AL20+0.15*AN20+0.1*AO20+0.1*AQ20+0.1*AP20 -> 0.24837054 | AS20: =RANK(AR20,AR:AR,FALSE) -> 1330 | AT20: =(max(AS:AS)-AS20)/(max(AS:AS)-min(AS:AS)) -> 0.40643144 | AU20: =if(AT20<0.5,"Low", if(and(AT20>=0.5,AT20<0.74),"Mid","High")) -> Low
